<?xml version="1.0" encoding="utf-8"?>
<!-- This URDF was automatically created by SolidWorks to URDF Exporter! Originally created by Stephen Brawner (brawner@gmail.com) 
     Commit Version: 1.6.0-4-g7f85cfe  Build Version: 1.6.7995.38578
     For more information, please see http://wiki.ros.org/sw_urdf_exporter -->
<robot
  name="big bipedal robot v1">
  <link name="dummy_link"/>  
  <joint name="dummy_joint" type="floating">
    <parent link="dummy_link"/>
    <child link="base_link"/>
    <origin xyz="0 0 0" rpy="0 0 0"/>
  </joint>
  <link
    name="base_link">
    <inertial>
      <origin
        xyz="0.027551 -0.015841 0.0099587"
        rpy="0 0 0" />
      <mass
        value="4.5" />
      <inertia
        ixx="0.0034237"
        ixy="0.00030912"
        ixz="-1.3025E-06"
        iyy="0.0045382"
        iyz="1.1414E-06"
        izz="0.003454" />
    </inertial>
    <visual>
      <origin
        xyz="0 0 0"
        rpy="0 0 0" />
      <geometry>
        <mesh
          filename="package://big bipedal robot v1/meshes/base_link.STL" />
      </geometry>
      <material
        name="">
        <color
          rgba="0.62745 0.62745 0.62745 1" />
      </material>
    </visual>
    <collision>
      <origin
        xyz="0 0 0"
        rpy="0 0 0" />
      <geometry>
        <mesh
          filename="package://big bipedal robot v1/meshes/base_link.STL" />
      </geometry>
    </collision>
  </link>
  <link
    name="hipR_link">
    <inertial>
      <origin
        xyz="0.050012 -8.4172E-05 -0.00066363"
        rpy="0 0 0" />
      <mass
        value="0.575" />
      <inertia
        ixx="0.00013072"
        ixy="3.5562E-07"
        ixz="-3.3092E-06"
        iyy="0.00015128"
        iyz="-2.3793E-07"
        izz="0.00024737" />
    </inertial>
    <visual>
      <origindummy_link
        xyz="0 0 0"
        rpy="0 0 0" />
      <geometry>
        <mesh
          filename="package://big bipedal robot v1/meshes/hipR_link.STL" />
      </geometry>
      <material
        name="">
        <color
          rgba="0.62745 0.62745 0.62745 1" />
      </material>
    </visual>
    <collision>
      <origin
        xyz="0 0 0"
        rpy="0 0 0" />
      <geometry>
        <mesh
          filename="package://big bipedal robot v1/meshes/hipR_link.STL" />
      </geometry>
    </collision>
  </link>
  <joint
    name="hip1"
    type="revolute">
    <origin
      xyz="0.02095 0.04625 0"
      rpy="1.5708 0 0" />
    <parent
      link="base_link" />
    <child
      link="hipR_link" />
    <axis
      xyz="1 0 0" />
    <limit
      lower="-0.34907"
      upper="0.34907"
      effort="0"
      velocity="0" />
  </joint>
  <link
    name="thighR_link">
    <inertial>
      <origin
        xyz="-6.2397E-05 -0.02137 -0.039555"
        rpy="0 0 0" />
      <mass
        value="1.01" />
      <inertia
        ixx="0.001452"
        ixy="1.5171E-08"
        ixz="3.2362E-07"
        iyy="0.00038047"
        iyz="-0.0002033"
        izz="0.0014985" />
    </inertial>
    <visual>
      <origin
        xyz="0 0 0"
        rpy="0 0 0" />
      <geometry>
        <mesh
          filename="package://big bipedal robot v1/meshes/thighR_link.STL" />
      </geometry>
      <material
        name="">
        <color
          rgba="0.62745 0.62745 0.62745 1" />
      </material>
    </visual>
    <collision>
      <origin
        xyz="0 0 0"
        rpy="0 0 0" />
      <geometry>
        <mesh
          filename="package://big bipedal robot v1/meshes/thighR_link.STL" />
      </geometry>
    </collision>
  </link>
  <joint
    name="thigh2"
    type="revolute">
    <origin
      xyz="0.05325 0 -0.019903"
      rpy="0 0 0" />
    <parent
      link="hipR_link" />
    <child
      link="thighR_link" />
    <axis
      xyz="0 0 1" />
    <limit
      lower="-1.7453"
      upper="0"
      effort="0"
      velocity="0" />
  </joint>
  <link
    name="calfR_link">
    <inertial>
      <origin
        xyz="3.3109E-05 -0.1669 -0.041645"
        rpy="0 0 0" />
      <mass
        value="0.605" />
      <inertia
        ixx="0.0013877"
        ixy="-9.3452E-07"
        ixz="6.3494E-09"
        iyy="0.00010149"
        iyz="5.0924E-06"
        izz="0.0013734" />
    </inertial>
    <visual>
      <origin
        xyz="0 0 0"
        rpy="0 0 0" />
      <geometry>
        <mesh
          filename="package://big bipedal robot v1/meshes/calfR_link.STL" />
      </geometry>
      <material
        name="">
        <color
          rgba="0.96078 0.96078 0.96471 1" />
      </material>
    </visual>
    <collision>
      <origin
        xyz="0 0 0"
        rpy="0 0 0" />
      <geometry>
        <mesh
          filename="package://big bipedal robot v1/meshes/calfR_link.STL" />
      </geometry>
    </collision>
  </link>
  <joint
    name="calf3"
    type="revolute">
    <origin
      xyz="0 -0.215 -0.022247"
      rpy="0 0 0" />
    <parent
      link="thighR_link" />
    <child
      link="calfR_link" />
    <axis
      xyz="0 0 1" />
    <limit
      lower="-2.618"
      upper="0"
      effort="0"
      velocity="0" />
  </joint>
  <link
    name="wheelR_link">
    <inertial>
      <origin
        xyz="6.1926E-11 1.06E-05 -0.024241"
        rpy="0 0 0" />
      <!-- <mass
        value="0.695" /> -->
      <mass
        value="0.0" />
      <inertia
        ixx="0.00097474"
        ixy="1.4305E-09"
        ixz="-1.6779E-09"
        iyy="0.00097477"
        iyz="-1.4591E-08"
        izz="0.001795" />
    </inertial>
    <visual>
      <origin
        xyz="0 0 0"
        rpy="0 0 0" />
      <geometry>
        <mesh
          filename="package://big bipedal robot v1/meshes/wheelR_link.STL" />
      </geometry>
      <material
        name="">
        <color
          rgba="0.15294 0.15294 0.15294 1" />
      </material>
    </visual>
    <collision>
      <origin
        xyz="0 0 0"
        rpy="0 0 0" />
      <geometry>
        <mesh
          filename="package://big bipedal robot v1/meshes/wheelR_link.STL" />
      </geometry>
    </collision>
  </link>
  <joint
    name="wheel4"
    type="continuous">
    <origin
      xyz="0 -0.215 -0.0596"
      rpy="0 0 0.059474" />
    <parent
      link="calfR_link" />
    <child
      link="wheelR_link" />
    <axis
      xyz="0 0 1" />
  </joint>
  <link
    name="hipL_link">
    <inertial>
      <origin
        xyz="0.050012 -8.4178E-05 0.00066363"
        rpy="0 0 0" />
      <mass
        value="0.575" />
      <inertia
        ixx="0.00013072"
        ixy="3.5562E-07"
        ixz="-3.3092E-06"
        iyy="0.00015128"
        iyz="-2.3793E-07"
        izz="0.00024737" />
    </inertial>
    <visual>
      <origin
        xyz="0 0 0"
        rpy="0 0 0" />
      <geometry>
        <mesh
          filename="package://big bipedal robot v1/meshes/hipL_link.STL" />
      </geometry>
      <material
        name="">
        <color
          rgba="0.62745 0.62745 0.62745 1" />
      </material>
    </visual>
    <collision>
      <origin
        xyz="0 0 0"
        rpy="0 0 0" />
      <geometry>
        <mesh
          filename="package://big bipedal robot v1/meshes/hipL_link.STL" />
      </geometry>
    </collision>
  </link>
  <joint
    name="hip01"
    type="revolute">
    <origin
      xyz="0.02195 -0.06625 0"
      rpy="1.5708 0 0" />
    <parent
      link="base_link" />
    <child
      link="hipL_link" />
    <axis
      xyz="1 0 0" />
    <limit
      lower="-0.34907"
      upper="0.34907"
      effort="0"
      velocity="0" />
  </joint>
  <link
    name="thighL_link">
    <inertial>
      <origin
        xyz="-6.2369E-05 -0.02137 0.039555"
        rpy="0 0 0" />
      <mass
        value="1.01" />
      <inertia
        ixx="0.001452"
        ixy="1.5255E-08"
        ixz="-3.236E-07"
        iyy="0.00038047"
        iyz="0.00020329"
        izz="0.0014985" />
    </inertial>
    <visual>
      <origin
        xyz="0 0 0"
        rpy="0 0 0" />
      <geometry>
        <mesh
          filename="package://big bipedal robot v1/meshes/thighL_link.STL" />
      </geometry>
      <material
        name="">
        <color
          rgba="0.62745 0.62745 0.62745 1" />
      </material>
    </visual>
    <collision>
      <origin
        xyz="0 0 0"
        rpy="0 0 0" />
      <geometry>
        <mesh
          filename="package://big bipedal robot v1/meshes/thighL_link.STL" />
      </geometry>
    </collision>
  </link>
  <joint
    name="thigh02"
    type="revolute">
    <origin
      xyz="0.05325 0 0.019903"
      rpy="0 0 0" />
    <parent
      link="hipL_link" />
    <child
      link="thighL_link" />
    <axis
      xyz="0 0 1" />
    <limit
      lower="-1.7453"
      upper="0"
      effort="0"
      velocity="0" />
  </joint>
  <link
    name="calfL_link">
    <inertial>
      <origin
        xyz="3.3129E-05 -0.1669 0.041645"
        rpy="0 0 0" />
      <mass
        value="0.605" />
      <inertia
        ixx="0.0013877"
        ixy="-9.3381E-07"
        ixz="-6.3843E-09"
        iyy="0.00010149"
        iyz="-5.0922E-06"
        izz="0.0013734" />
    </inertial>
    <visual>
      <origin
        xyz="0 0 0"
        rpy="0 0 0" />
      <geometry>
        <mesh
          filename="package://big bipedal robot v1/meshes/calfL_link.STL" />
      </geometry>
      <material
        name="">
        <color
          rgba="0.96078 0.96078 0.96471 1" />
      </material>
    </visual>
    <collision>
      <origin
        xyz="0 0 0"
        rpy="0 0 0" />
      <geometry>
        <mesh
          filename="package://big bipedal robot v1/meshes/calfL_link.STL" />
      </geometry>
    </collision>
  </link>
  <joint
    name="calf03"
    type="revolute">
    <origin
      xyz="0 -0.215 0.022247"
      rpy="0 0 0" />
    <parent
      link="thighL_link" />
    <child
      link="calfL_link" />
    <axis
      xyz="0 0 1" />
    <limit
      lower="0"
      upper="2.618"
      effort="0"
      velocity="0" />
  </joint>
  <link
    name="wheelL_link">
    <inertial>
      <origin
        xyz="-5.9355E-08 1.0557E-05 0.024241"
        rpy="0 0 0" />
      <!-- <mass
        value="0.695" /> -->
      <mass
        value="0.0" />
      <inertia
        ixx="0.00097474"
        ixy="1.3894E-09"
        ixz="1.4595E-09"
        iyy="0.00097477"
        iyz="1.4685E-08"
        izz="0.001795" />
    </inertial>
    <visual>
      <origin
        xyz="0 0 0"
        rpy="0 0 0" />
      <geometry>
        <mesh
          filename="package://big bipedal robot v1/meshes/wheelL_link.STL" />
      </geometry>
      <material
        name="">
        <color
          rgba="0.15294 0.15294 0.15294 1" />
      </material>
    </visual>
    <collision>
      <origin
        xyz="0 0 0"
        rpy="0 0 0" />
      <geometry>
        <mesh
          filename="package://big bipedal robot v1/meshes/wheelL_link.STL" />
      </geometry>
    </collision>
  </link>
  <joint
    name="wheel04"
    type="continuous">
    <origin
      xyz="0 -0.215 0.0596"
      rpy="0 0 -2.7517" />
    <parent
      link="calfL_link" />
    <child
      link="wheelL_link" />
    <axis
      xyz="0 0 1" />
  </joint>
</robot>